Workbook

Sheet Accueil
B1: HUB QUILL
B2: Suivi des formations des agents — Montréal & Lisbonne
B4: EN UN COUP D’ŒIL
B5: Agents actifs | C5: =COUNTIF(Skills!M:M,"Active") -> 147
B6: Formations en cours | C6: =SUM(Pipeline!K400:K4395) -> 19
B7: Agents en arrêt (maladie) | C7: =COUNTIF(Skills!M:M,"Maladie") -> 3
B9: COMMENT ÇA MARCHE
B10: • Les cellules dorées sont à remplir ; tout ce qui est bleu est automatique.
B11: • Le Pipeline et le Tableau de bord se mettent à jour tout seuls.
B12: • Marquez une formation « Terminé » dans son onglet : elle quitte le Pipeline.
B14: QUE VOULEZ-VOUS FAIRE ?
B15: Astuce : Ctrl + clic (Cmd + clic sur Mac) sur un lien pour ouvrir l’onglet.
B16: =HYPERLINK("#'Pipeline'!A1","→ Voir les formations en cours") -> → Voir les formations en cours
B17: =HYPERLINK("#'Tableau de Bord'!A1","→ Tableau de bord (indicateurs)") -> → Tableau de bord (indicateurs)
B18: =HYPERLINK("#'Skills'!A1","→ Compétences et agents") -> → Compétences et agents
B19: =HYPERLINK("#'Formation Initiale'!A1","→ Formation initiale (B2C / B2B)") -> → Formation initiale (B2C / B2B)
B20: =HYPERLINK("#'Agences & Après-vente'!A1","→ Nouvelle compétence — Agences & Après-vente") -> → Nouvelle compétence — Agences & Après-vente
B21: =HYPERLINK("#'Evermont'!A1","→ Nouvelle compétence — Evermont") -> → Nouvelle compétence — Evermont
B22: =HYPERLINK("#'Planner'!A1","→ Calendrier des cohortes (Planner)") -> → Calendrier des cohortes (Planner)
B23: =HYPERLINK("#'Mode d''emploi'!A1","→ Mode d’emploi") -> → Mode d’emploi
B25: LÉGENDE
B26: Cellule à remplir (vous écrivez ici)
B27: Cellule automatique — ne pas modifier
B29: Onglets : verts = saisie · bleus = automatiques · gris = références.

Sheet Tableau de Bord
A1: HUB FORMATION QUILL · TABLEAU DE BORD
A2: ="Vue d'ensemble des formations · Mis à jour le "&TEXT(TODAY(),"dddd dd mmmm yyyy") -> Vue d'ensemble des formations · Mis à jour le Friday 19 June 2026
A3: =HYPERLINK("#Accueil!A1","⌂ Accueil") -> ⌂ Accueil
A4: ▌ INDICATEURS CLÉS
A6: AGENTS TOTAUX | C6: AGENTS MONTRÉAL | E6: AGENTS LISBONNE | G6: GROUPES ACTIFS | I6: EN FORMATION
A7: =COUNTIFS(Skills!$A$2:$A$999,"?*",Skills!$M$2:$M$999,"Active") -> 147 | C7: =COUNTIFS(Skills!$D$2:$D$999,"Montréal",Skills!$M$2:$M$999,"Active") -> 112 | E7: =COUNTIFS(Skills!$D$2:$D$999,"Lisbonne",Skills!$M$2:$M$999,"Active") -> 35 | G7: =SUMPRODUCT(IFERROR(1/COUNTIFS('Formation Initiale'!$B$2:$B$999,'Formation Initiale'!$B$2:$B$999,'Formation Initiale'!$R$2:$R$999,"En cours"),0)*('Formation Initiale'!$R$2:$R$999="En cours")) -> 2 | I7: =COUNTIF('Formation Initiale'!$R$2:$R$999,"En cours")+COUNTIF('Agences & Après-vente'!$I$2:$I$1000,"En cours")+COUNTIF(Evermont!$Q$2:$Q$1000,"En cours") -> 18
A9: ▌ COUVERTURE DES COMPÉTENCES
A11: B2C | B11: B2B | C11: Agences B2C | D11: Agences B2B | E11: Après-vente B2C | F11: Après-vente B2B | G11: Evermont
A12: =COUNTIFS(Skills!$E$2:$E$999,"✓",Skills!$M$2:$M$999,"Active") -> 132 | B12: =COUNTIFS(Skills!$F$2:$F$999,"✓",Skills!$M$2:$M$999,"Active") -> 97 | C12: =COUNTIFS(Skills!$G$2:$G$999,"✓",Skills!$M$2:$M$999,"Active") -> 101 | D12: =COUNTIFS(Skills!$H$2:$H$999,"✓",Skills!$M$2:$M$999,"Active") -> 79 | E12: =COUNTIFS(Skills!$I$2:$I$999,"✓",Skills!$M$2:$M$999,"Active") -> 95 | F12: =COUNTIFS(Skills!$J$2:$J$999,"✓",Skills!$M$2:$M$999,"Active") -> 76 | G12: =COUNTIFS(Skills!$K$2:$K$999,"✓",Skills!$M$2:$M$999,"Active") -> 61
A13: ="/ "&COUNTIFS(Skills!$A$2:$A$999,"?*",Skills!$M$2:$M$999,"Active") -> / 147 | B13: ="/ "&COUNTIFS(Skills!$D$2:$D$999,"Montréal",Skills!$M$2:$M$999,"Active") -> / 112 | C13: ="/ "&COUNTIFS(Skills!$A$2:$A$999,"?*",Skills!$M$2:$M$999,"Active") -> / 147 | D13: ="/ "&COUNTIFS(Skills!$D$2:$D$999,"Montréal",Skills!$M$2:$M$999,"Active") -> / 112 | E13: ="/ "&COUNTIFS(Skills!$A$2:$A$999,"?*",Skills!$M$2:$M$999,"Active") -> / 147 | F13: ="/ "&COUNTIFS(Skills!$D$2:$D$999,"Montréal",Skills!$M$2:$M$999,"Active") -> / 112 | G13: ="/ "&COUNTIFS(Skills!$A$2:$A$999,"?*",Skills!$M$2:$M$999,"Active") -> / 147
A15: ▌ STATUT DES FORMATIONS (Cumul: B2C/B2B + Agences/Après-vente + Evermont)
A17: TERMINÉES | C17: EN COURS | E17: À VENIR | G17: PROG. MOYENNE | I17: % AGENTS PRÊTS
A18: =COUNTIF('Formation Initiale'!$R$2:$R$999,"Terminé")+COUNTIF('Agences & Après-vente'!$I$2:$I$1000,"DONE")+COUNTIF(Evermont!$Q$2:$Q$1000,"Terminé") -> 261 | C18: =COUNTIF('Formation Initiale'!$R$2:$R$999,"En cours")+COUNTIF('Agences & Après-vente'!$I$2:$I$1000,"En cours")+COUNTIF(Evermont!$Q$2:$Q$1000,"En cours") -> 18 | E18: =COUNTIF('Formation Initiale'!$R$2:$R$999,"À venir")+COUNTIF('Agences & Après-vente'!$I$2:$I$1000,"À venir")+COUNTIF(Evermont!$Q$2:$Q$1000,"À venir") -> 1 | G18: =IFERROR(AVERAGEIFS('Formation Initiale'!$M$2:$M$999,'Formation Initiale'!$R$2:$R$999,"En cours"),0) -> 0.166 | I18: =IFERROR(COUNTIF('Formation Initiale'!$W$2:$W$999,"Y")/COUNTIF(Skills!$A$2:$A$999,"?*"),0) -> 0.37853107
A20: ▌ RÉPARTITION PAR PRIORITÉ (Formations en cours)
A22: P1 — CRITIQUE (retard ≥12%) | C22: P2 — À SURVEILLER (retard ≥6%) | E22: P3 — SUR LA VOIE (retard <6%) | G22: NON ÉVALUÉS
A23: =COUNTIF('Formation Initiale'!$P$2:$P$999,"P1") -> 20 | C23: =COUNTIF('Formation Initiale'!$P$2:$P$999,"P2") -> 7 | E23: =COUNTIF('Formation Initiale'!$P$2:$P$999,"P3") -> 70 | G23: =SUMPRODUCT(('Formation Initiale'!$R$2:$R$999="En cours")*('Formation Initiale'!$P$2:$P$999="")) -> 0
A25: ▌ RÉPARTITION PAR SITE
A27: Site | B27: Total Agents | C27: En Formation | D27: B2C | E27: B2B | F27: Agences B2C | G27: Agences B2B | H27: Après-vente B2C | I27: Après-vente B2B | J27: Evermont | K27: % Prêts
A28: 🇨🇦 Montréal | B28: =COUNTIFS(Skills!$D$2:$D$999,"Montréal",Skills!$M$2:$M$999,"Active") -> 112 | C28: =COUNTIFS('Formation Initiale'!$R$2:$R$999,"En cours",'Formation Initiale'!$F$2:$F$999,"Montréal") -> 15 | D28: =COUNTIFS(Skills!$E$2:$E$999,"✓",Skills!$D$2:$D$999,"Montréal",Skills!$M$2:$M$999,"Active") -> 97 | E28: =COUNTIFS(Skills!$F$2:$F$999,"✓",Skills!$D$2:$D$999,"Montréal",Skills!$M$2:$M$999,"Active") -> 97 | F28: =COUNTIFS(Skills!$G$2:$G$999,"✓",Skills!$D$2:$D$999,"Montréal",Skills!$M$2:$M$999,"Active") -> 79 | G28: =COUNTIFS(Skills!$H$2:$H$999,"✓",Skills!$D$2:$D$999,"Montréal",Skills!$M$2:$M$999,"Active") -> 79 | H28: =COUNTIFS(Skills!$I$2:$I$999,"✓",Skills!$D$2:$D$999,"Montréal",Skills!$M$2:$M$999,"Active") -> 76 | I28: =COUNTIFS(Skills!$J$2:$J$999,"✓",Skills!$D$2:$D$999,"Montréal",Skills!$M$2:$M$999,"Active") -> 76 | J28: =COUNTIFS(Skills!$K$2:$K$999,"✓",Skills!$D$2:$D$999,"Montréal",Skills!$M$2:$M$999,"Active") -> 61 | K28: =IFERROR(COUNTIFS('Formation Initiale'!$W$2:$W$999,"Y",'Formation Initiale'!$F$2:$F$999,"Montréal")/COUNTIFS('Formation Initiale'!$F$2:$F$999,"Montréal"),0) -> 0.45454545
A29: 🇵🇹 Lisbonne | B29: =COUNTIFS(Skills!$D$2:$D$999,"Lisbonne",Skills!$M$2:$M$999,"Active") -> 35 | C29: =COUNTIFS('Formation Initiale'!$R$2:$R$999,"En cours",'Formation Initiale'!$F$2:$F$999,"Lisbonne") -> 0 | D29: =COUNTIFS(Skills!$E$2:$E$999,"✓",Skills!$D$2:$D$999,"Lisbonne",Skills!$M$2:$M$999,"Active") -> 35 | E29: =COUNTIFS(Skills!$F$2:$F$999,"✓",Skills!$D$2:$D$999,"Lisbonne",Skills!$M$2:$M$999,"Active") -> 0 | F29: =COUNTIFS(Skills!$G$2:$G$999,"✓",Skills!$D$2:$D$999,"Lisbonne",Skills!$M$2:$M$999,"Active") -> 22 | G29: =COUNTIFS(Skills!$H$2:$H$999,"✓",Skills!$D$2:$D$999,"Lisbonne",Skills!$M$2:$M$999,"Active") -> 0 | H29: =COUNTIFS(Skills!$I$2:$I$999,"✓",Skills!$D$2:$D$999,"Lisbonne",Skills!$M$2:$M$999,"Active") -> 19 | I29: =COUNTIFS(Skills!$J$2:$J$999,"✓",Skills!$D$2:$D$999,"Lisbonne",Skills!$M$2:$M$999,"Active") -> 0 | J29: =COUNTIFS(Skills!$K$2:$K$999,"✓",Skills!$D$2:$D$999,"Lisbonne",Skills!$M$2:$M$999,"Active") -> 0 | K29: =IFERROR(COUNTIFS('Formation Initiale'!$W$2:$W$999,"Y",'Formation Initiale'!$F$2:$F$999,"Lisbonne")/COUNTIFS('Formation Initiale'!$F$2:$F$999,"Lisbonne"),0) -> 0.88679245
A30: 🌍 TOTAL | B30: =COUNTIFS(Skills!$A$2:$A$999,"?*",Skills!$M$2:$M$999,"Active") -> 147 | C30: =COUNTIF('Formation Initiale'!$R$2:$R$999,"En cours") -> 15 | D30: =COUNTIFS(Skills!$E$2:$E$999,"✓",Skills!$M$2:$M$999,"Active") -> 132 | E30: =COUNTIFS(Skills!$F$2:$F$999,"✓",Skills!$M$2:$M$999,"Active") -> 97 | F30: =COUNTIFS(Skills!$G$2:$G$999,"✓",Skills!$M$2:$M$999,"Active") -> 101 | G30: =COUNTIFS(Skills!$H$2:$H$999,"✓",Skills!$M$2:$M$999,"Active") -> 79 | H30: =COUNTIFS(Skills!$I$2:$I$999,"✓",Skills!$M$2:$M$999,"Active") -> 95 | I30: =COUNTIFS(Skills!$J$2:$J$999,"✓",Skills!$M$2:$M$999,"Active") -> 76 | J30: =COUNTIFS(Skills!$K$2:$K$999,"✓",Skills!$M$2:$M$999,"Active") -> 61 | K30: =IFERROR(COUNTIF('Formation Initiale'!$W$2:$W$999,"Y")/COUNTA('Formation Initiale'!$E$2:$E$999),0) -> 0.067134269
A33: ▌ STATUT PAR COHORTE (Formation initiale B2C/B2B)
A35: Cohorte | B35: Total | C35: Site | D35: Date début | E35: Date fin | F35: Terminés | G35: En cours | H35: % Complétion | I35: Prêts (Y)
A36: 173 | B36: =COUNTIF('Formation Initiale'!$B$2:$B$999,"173") -> 6 | C36: =IF(LEFT($A36,2)="OS","🇵🇹 Lisbonne","🇨🇦 Montréal") -> 🇨🇦 Montréal | D36: =IFERROR(_xlfn.MINIFS('Formation Initiale'!$G$2:$G$999,'Formation Initiale'!$B$2:$B$999,"173"),"") -> 46056 | E36: =IFERROR(_xlfn.MAXIFS('Formation Initiale'!$H$2:$H$999,'Formation Initiale'!$B$2:$B$999,"173"),"") -> 46070 | F36: =COUNTIFS('Formation Initiale'!$B$2:$B$999,"173",'Formation Initiale'!$R$2:$R$999,"Terminé") -> 6 | G36: =COUNTIFS('Formation Initiale'!$B$2:$B$999,"173",'Formation Initiale'!$R$2:$R$999,"En cours") -> 0 | H36: =IFERROR(COUNTIFS('Formation Initiale'!$B$2:$B$999,"173",'Formation Initiale'!$R$2:$R$999,"Terminé")/COUNTIF('Formation Initiale'!$B$2:$B$999,"173"),0) -> 1 | I36: =COUNTIFS('Formation Initiale'!$B$2:$B$999,"173",'Formation Initiale'!$W$2:$W$999,"Y") -> 6
A37: 174 | B37: =COUNTIF('Formation Initiale'!$B$2:$B$999,"174") -> 5 | C37: =IF(LEFT($A37,2)="OS","🇵🇹 Lisbonne","🇨🇦 Montréal") -> 🇨🇦 Montréal | D37: =IFERROR(_xlfn.MINIFS('Formation Initiale'!$G$2:$G$999,'Formation Initiale'!$B$2:$B$999,"174"),"") -> 46099 | E37: =IFERROR(_xlfn.MAXIFS('Formation Initiale'!$H$2:$H$999,'Formation Initiale'!$B$2:$B$999,"174"),"") -> 46114 | F37: =COUNTIFS('Formation Initiale'!$B$2:$B$999,"174",'Formation Initiale'!$R$2:$R$999,"Terminé") -> 5 | G37: =COUNTIFS('Formation Initiale'!$B$2:$B$999,"174",'Formation Initiale'!$R$2:$R$999,"En cours") -> 0 | H37: =IFERROR(COUNTIFS('Formation Initiale'!$B$2:$B$999,"174",'Formation Initiale'!$R$2:$R$999,"Terminé")/COUNTIF('Formation Initiale'!$B$2:$B$999,"174"),0) -> 1 | I37: =COUNTIFS('Formation Initiale'!$B$2:$B$999,"174",'Formation Initiale'!$W$2:$W$999,"Y") -> 5
A38: 175 | B38: =COUNTIF('Formation Initiale'!$B$2:$B$999,"175") -> 8 | C38: =IF(LEFT($A38,2)="OS","🇵🇹 Lisbonne","🇨🇦 Montréal") -> 🇨🇦 Montréal | D38: =IFERROR(_xlfn.MINIFS('Formation Initiale'!$G$2:$G$999,'Formation Initiale'!$B$2:$B$999,"175"),"") -> 46125 | E38: =IFERROR(_xlfn.MAXIFS('Formation Initiale'!$H$2:$H$999,'Formation Initiale'!$B$2:$B$999,"175"),"") -> 46139 | F38: =COUNTIFS('Formation Initiale'!$B$2:$B$999,"175",'Formation Initiale'!$R$2:$R$999,"Terminé") -> 8 | G38: =COUNTIFS('Formation Initiale'!$B$2:$B$999,"175",'Formation Initiale'!$R$2:$R$999,"En cours") -> 0 | H38: =IFERROR(COUNTIFS('Formation Initiale'!$B$2:$B$999,"175",'Formation Initiale'!$R$2:$R$999,"Terminé")/COUNTIF('Formation Initiale'!$B$2:$B$999,"175"),0) -> 1 | I38: =COUNTIFS('Formation Initiale'!$B$2:$B$999,"175",'Formation Initiale'!$W$2:$W$999,"Y") -> 8
A39: 176 | B39: =COUNTIF('Formation Initiale'!$B$2:$B$999,"176") -> 1 | C39: =IF(LEFT($A39,2)="OS","🇵🇹 Lisbonne","🇨🇦 Montréal") -> 🇨🇦 Montréal | D39: =IFERROR(_xlfn.MINIFS('Formation Initiale'!$G$2:$G$999,'Formation Initiale'!$B$2:$B$999,"176"),"") -> 46146 | E39: =IFERROR(_xlfn.MAXIFS('Formation Initiale'!$H$2:$H$999,'Formation Initiale'!$B$2:$B$999,"176"),"") -> 46161 | F39: =COUNTIFS('Formation Initiale'!$B$2:$B$999,"176",'Formation Initiale'!$R$2:$R$999,"Terminé") -> 1 | G39: =COUNTIFS('Formation Initiale'!$B$2:$B$999,"176",'Formation Initiale'!$R$2:$R$999,"En cours") -> 0 | H39: =IFERROR(COUNTIFS('Formation Initiale'!$B$2:$B$999,"176",'Formation Initiale'!$R$2:$R$999,"Terminé")/COUNTIF('Formation Initiale'!$B$2:$B$999,"176"),0) -> 1 | I39: =COUNTIFS('Formation Initiale'!$B$2:$B$999,"176",'Formation Initiale'!$W$2:$W$999,"Y") -> 1
A40: 177 | B40: =COUNTIF('Formation Initiale'!$B$2:$B$999,"177") -> 9 | C40: =IF(LEFT($A40,2)="OS","🇵🇹 Lisbonne","🇨🇦 Montréal") -> 🇨🇦 Montréal | D40: =IFERROR(_xlfn.MINIFS('Formation Initiale'!$G$2:$G$999,'Formation Initiale'!$B$2:$B$999,"177"),"") -> 46167 | E40: =IFERROR(_xlfn.MAXIFS('Formation Initiale'!$H$2:$H$999,'Formation Initiale'!$B$2:$B$999,"177"),"") -> 46181 | F40: =COUNTIFS('Formation Initiale'!$B$2:$B$999,"177",'Formation Initiale'!$R$2:$R$999,"Terminé") -> 9 | G40: =COUNTIFS('Formation Initiale'!$B$2:$B$999,"177",'Formation Initiale'!$R$2:$R$999,"En cours") -> 0 | H40: =IFERROR(COUNTIFS('Formation Initiale'!$B$2:$B$999,"177",'Formation Initiale'!$R$2:$R$999,"Terminé")/COUNTIF('Formation Initiale'!$B$2:$B$999,"177"),0) -> 1 | I40: =COUNTIFS('Formation Initiale'!$B$2:$B$999,"177",'Formation Initiale'!$W$2:$W$999,"Y") -> 0
A41: OS1 | B41: =COUNTIF('Formation Initiale'!$B$2:$B$999,"OS1") -> 13 | C41: =IF(LEFT($A41,2)="OS","🇵🇹 Lisbonne","🇨🇦 Montréal") -> 🇵🇹 Lisbonne | D41: =IFERROR(_xlfn.MINIFS('Formation Initiale'!$G$2:$G$999,'Formation Initiale'!$B$2:$B$999,"OS1"),"") -> 46006 | E41: =IFERROR(_xlfn.MAXIFS('Formation Initiale'!$H$2:$H$999,'Formation Initiale'!$B$2:$B$999,"OS1"),"") -> 46017 | F41: =COUNTIFS('Formation Initiale'!$B$2:$B$999,"OS1",'Formation Initiale'!$R$2:$R$999,"Terminé") -> 13 | G41: =COUNTIFS('Formation Initiale'!$B$2:$B$999,"OS1",'Formation Initiale'!$R$2:$R$999,"En cours") -> 0 | H41: =IFERROR(COUNTIFS('Formation Initiale'!$B$2:$B$999,"OS1",'Formation Initiale'!$R$2:$R$999,"Terminé")/COUNTIF('Formation Initiale'!$B$2:$B$999,"OS1"),0) -> 1 | I41: =COUNTIFS('Formation Initiale'!$B$2:$B$999,"OS1",'Formation Initiale'!$W$2:$W$999,"Y") -> 13
A42: OS2 | B42: =COUNTIF('Formation Initiale'!$B$2:$B$999,"OS2") -> 5 | C42: =IF(LEFT($A42,2)="OS","🇵🇹 Lisbonne","🇨🇦 Montréal") -> 🇵🇹 Lisbonne | D42: =IFERROR(_xlfn.MINIFS('Formation Initiale'!$G$2:$G$999,'Formation Initiale'!$B$2:$B$999,"OS2"),"") -> 46027 | E42: =IFERROR(_xlfn.MAXIFS('Formation Initiale'!$H$2:$H$999,'Formation Initiale'!$B$2:$B$999,"OS2"),"") -> 46038 | F42: =COUNTIFS('Formation Initiale'!$B$2:$B$999,"OS2",'Formation Initiale'!$R$2:$R$999,"Terminé") -> 5 | G42: =COUNTIFS('Formation Initiale'!$B$2:$B$999,"OS2",'Formation Initiale'!$R$2:$R$999,"En cours") -> 0 | H42: =IFERROR(COUNTIFS('Formation Initiale'!$B$2:$B$999,"OS2",'Formation Initiale'!$R$2:$R$999,"Terminé")/COUNTIF('Formation Initiale'!$B$2:$B$999,"OS2"),0) -> 1 | I42: =COUNTIFS('Formation Initiale'!$B$2:$B$999,"OS2",'Formation Initiale'!$W$2:$W$999,"Y") -> 5
A43: OS3 | B43: =COUNTIF('Formation Initiale'!$B$2:$B$999,"OS3") -> 9 | C43: =IF(LEFT($A43,2)="OS","🇵🇹 Lisbonne","🇨🇦 Montréal") -> 🇵🇹 Lisbonne | D43: =IFERROR(_xlfn.MINIFS('Formation Initiale'!$G$2:$G$999,'Formation Initiale'!$B$2:$B$999,"OS3"),"") -> 46034 | E43: =IFERROR(_xlfn.MAXIFS('Formation Initiale'!$H$2:$H$999,'Formation Initiale'!$B$2:$B$999,"OS3"),"") -> 46045 | F43: =COUNTIFS('Formation Initiale'!$B$2:$B$999,"OS3",'Formation Initiale'!$R$2:$R$999,"Terminé") -> 9 | G43: =COUNTIFS('Formation Initiale'!$B$2:$B$999,"OS3",'Formation Initiale'!$R$2:$R$999,"En cours") -> 0 | H43: =IFERROR(COUNTIFS('Formation Initiale'!$B$2:$B$999,"OS3",'Formation Initiale'!$R$2:$R$999,"Terminé")/COUNTIF('Formation Initiale'!$B$2:$B$999,"OS3"),0) -> 1 | I43: =COUNTIFS('Formation Initiale'!$B$2:$B$999,"OS3",'Formation Initiale'!$W$2:$W$999,"Y") -> 9
A44: OS4 | B44: =COUNTIF('Formation Initiale'!$B$2:$B$999,"OS4") -> 5 | C44: =IF(LEFT($A44,2)="OS","🇵🇹 Lisbonne","🇨🇦 Montréal") -> 🇵🇹 Lisbonne | D44: =IFERROR(_xlfn.MINIFS('Formation Initiale'!$G$2:$G$999,'Formation Initiale'!$B$2:$B$999,"OS4"),"") -> 46043 | E44: =IFERROR(_xlfn.MAXIFS('Formation Initiale'!$H$2:$H$999,'Formation Initiale'!$B$2:$B$999,"OS4"),"") -> 46056 | F44: =COUNTIFS('Formation Initiale'!$B$2:$B$999,"OS4",'Formation Initiale'!$R$2:$R$999,"Terminé") -> 5 | G44: =COUNTIFS('Formation Initiale'!$B$2:$B$999,"OS4",'Formation Initiale'!$R$2:$R$999,"En cours") -> 0 | H44: =IFERROR(COUNTIFS('Formation Initiale'!$B$2:$B$999,"OS4",'Formation Initiale'!$R$2:$R$999,"Terminé")/COUNTIF('Formation Initiale'!$B$2:$B$999,"OS4"),0) -> 1 | I44: =COUNTIFS('Formation Initiale'!$B$2:$B$999,"OS4",'Formation Initiale'!$W$2:$W$999,"Y") -> 5
A45: OS5 | B45: =COUNTIF('Formation Initiale'!$B$2:$B$999,"OS5") -> 5 | C45: =IF(LEFT($A45,2)="OS","🇵🇹 Lisbonne","🇨🇦 Montréal") -> 🇵🇹 Lisbonne | D45: =IFERROR(_xlfn.MINIFS('Formation Initiale'!$G$2:$G$999,'Formation Initiale'!$B$2:$B$999,"OS5"),"") -> 46111 | E45: =IFERROR(_xlfn.MAXIFS('Formation Initiale'!$H$2:$H$999,'Formation Initiale'!$B$2:$B$999,"OS5"),"") -> 46122 | F45: =COUNTIFS('Formation Initiale'!$B$2:$B$999,"OS5",'Formation Initiale'!$R$2:$R$999,"Terminé") -> 5 | G45: =COUNTIFS('Formation Initiale'!$B$2:$B$999,"OS5",'Formation Initiale'!$R$2:$R$999,"En cours") -> 0 | H45: =IFERROR(COUNTIFS('Formation Initiale'!$B$2:$B$999,"OS5",'Formation Initiale'!$R$2:$R$999,"Terminé")/COUNTIF('Formation Initiale'!$B$2:$B$999,"OS5"),0) -> 1 | I45: =COUNTIFS('Formation Initiale'!$B$2:$B$999,"OS5",'Formation Initiale'!$W$2:$W$999,"Y") -> 5
A46: OS6 | B46: =COUNTIF('Formation Initiale'!$B$2:$B$999,"OS6") -> 4 | C46: =IF(LEFT($A46,2)="OS","🇵🇹 Lisbonne","🇨🇦 Montréal") -> 🇵🇹 Lisbonne | D46: =IFERROR(_xlfn.MINIFS('Formation Initiale'!$G$2:$G$999,'Formation Initiale'!$B$2:$B$999,"OS6"),"") -> 46132 | E46: =IFERROR(_xlfn.MAXIFS('Formation Initiale'!$H$2:$H$999,'Formation Initiale'!$B$2:$B$999,"OS6"),"") -> 46143 | F46: =COUNTIFS('Formation Initiale'!$B$2:$B$999,"OS6",'Formation Initiale'!$R$2:$R$999,"Terminé") -> 4 | G46: =COUNTIFS('Formation Initiale'!$B$2:$B$999,"OS6",'Formation Initiale'!$R$2:$R$999,"En cours") -> 0 | H46: =IFERROR(COUNTIFS('Formation Initiale'!$B$2:$B$999,"OS6",'Formation Initiale'!$R$2:$R$999,"Terminé")/COUNTIF('Formation Initiale'!$B$2:$B$999,"OS6"),0) -> 1 | I46: =COUNTIFS('Formation Initiale'!$B$2:$B$999,"OS6",'Formation Initiale'!$W$2:$W$999,"Y") -> 4
A47: OS7 | B47: =COUNTIF('Formation Initiale'!$B$2:$B$999,"OS7") -> 6 | C47: =IF(LEFT($A47,2)="OS","🇵🇹 Lisbonne","🇨🇦 Montréal") -> 🇵🇹 Lisbonne | D47: =IFERROR(_xlfn.MINIFS('Formation Initiale'!$G$2:$G$999,'Formation Initiale'!$B$2:$B$999,"OS7"),"") -> 46139 | E47: =IFERROR(_xlfn.MAXIFS('Formation Initiale'!$H$2:$H$999,'Formation Initiale'!$B$2:$B$999,"OS7"),"") -> 46150 | F47: =COUNTIFS('Formation Initiale'!$B$2:$B$999,"OS7",'Formation Initiale'!$R$2:$R$999,"Terminé") -> 6 | G47: =COUNTIFS('Formation Initiale'!$B$2:$B$999,"OS7",'Formation Initiale'!$R$2:$R$999,"En cours") -> 0 | H47: =IFERROR(COUNTIFS('Formation Initiale'!$B$2:$B$999,"OS7",'Formation Initiale'!$R$2:$R$999,"Terminé")/COUNTIF('Formation Initiale'!$B$2:$B$999,"OS7"),0) -> 1 | I47: =COUNTIFS('Formation Initiale'!$B$2:$B$999,"OS7",'Formation Initiale'!$W$2:$W$999,"Y") -> 6
A50: ▌ ENTONNOIR DE PROGRESSION (Tous types de formation)
A52: Type de formation | B52: Sessions Total | C52: Terminées | D52: En cours | E52: À venir | F52: % Complétion
A53: Formation B2C/B2B | B53: =COUNTA('Formation Initiale'!$E$2:$E$999) -> 998 | C53: =COUNTIF('Formation Initiale'!$R$2:$R$999,"Terminé") -> 82 | D53: =COUNTIF('Formation Initiale'!$R$2:$R$999,"En cours") -> 15 | E53: =COUNTIF('Formation Initiale'!$R$2:$R$999,"À venir") -> 0 | F53: =IFERROR(C53/B53,0) -> 0.082164329
A54: Agences | B54: =COUNTIFS('Agences & Après-vente'!$D$2:$D$1000,"Agences")+COUNTIFS('Agences & Après-vente'!$D$2:$D$1000,"Agences et Après-vente") -> 82 | C54: =SUMPRODUCT((('Agences & Après-vente'!$D$2:$D$1000="Agences")+('Agences & Après-vente'!$D$2:$D$1000="Agences et Après-vente"))*('Agences & Après-vente'!$I$2:$I$1000="DONE")) -> 80 | D54: =SUMPRODUCT((('Agences & Après-vente'!$D$2:$D$1000="Agences")+('Agences & Après-vente'!$D$2:$D$1000="Agences et Après-vente"))*('Agences & Après-vente'!$I$2:$I$1000="En cours")) -> 2 | E54: =SUMPRODUCT((('Agences & Après-vente'!$D$2:$D$1000="Agences")+('Agences & Après-vente'!$D$2:$D$1000="Agences et Après-vente"))*('Agences & Après-vente'!$I$2:$I$1000="À venir")) -> 0 | F54: =IFERROR(C54/B54,0) -> 0.97560976
A55: Après-vente | B55: =COUNTIFS('Agences & Après-vente'!$D$2:$D$1000,"Après-vente")+COUNTIFS('Agences & Après-vente'!$D$2:$D$1000,"Agences et Après-vente") -> 91 | C55: =SUMPRODUCT((('Agences & Après-vente'!$D$2:$D$1000="Après-vente")+('Agences & Après-vente'!$D$2:$D$1000="Agences et Après-vente"))*('Agences & Après-vente'!$I$2:$I$1000="DONE")) -> 89 | D55: =SUMPRODUCT((('Agences & Après-vente'!$D$2:$D$1000="Après-vente")+('Agences & Après-vente'!$D$2:$D$1000="Agences et Après-vente"))*('Agences & Après-vente'!$I$2:$I$1000="En cours")) -> 2 | E55: =SUMPRODUCT((('Agences & Après-vente'!$D$2:$D$1000="Après-vente")+('Agences & Après-vente'!$D$2:$D$1000="Agences et Après-vente"))*('Agences & Après-vente'!$I$2:$I$1000="À venir")) -> 0 | F55: =IFERROR(C55/B55,0) -> 0.97802198
...

Sheet Pipeline
A1: PIPELINE — AGENTS EN FORMATION ACTIVE | N1: =HYPERLINK("#Accueil!A1","⌂ Accueil") -> ⌂ Accueil
A2: Formation en cours / à venir / à planifier · Auto-rempli depuis Active + Skills, Formation Initiale, Agences & Après-vente, Evermont
A3: Filtres : | B3: Lieu | C3: Tous | D3: Statut | E3: Tous
A6: ="FORMATION INITIALE — Formation Initiale · "&$L$799 -> FORMATION INITIALE — Formation Initiale · 15 | F6: ="NOUVELLE COMPÉTENCE — Agences & Après-vente · "&($L$1199-$L$799) -> NOUVELLE COMPÉTENCE — Agences & Après-vente · 2 | K6: ="NOUVELLE COMPÉTENCE — Evermont · "&($L$1599-$L$1199) -> NOUVELLE COMPÉTENCE — Evermont · 2
A7: ID | B7: Agent | C7: Jrs rest. | D7: Statut | F7: ID | G7: Agent | H7: Jrs rest. | I7: Statut | K7: ID | L7: Agent | M7: Jrs rest. | N7: Statut
A8: =IFERROR(INDEX($A:$A,MATCH(1,$L$400:$L$799,0)+399),"") -> TR163 | B8: =IFERROR(INDEX($B:$B,MATCH(1,$L$400:$L$799,0)+399),"") -> Rhoea Thornshaw | C8: =IFERROR(INDEX($H:$H,MATCH(1,$L$400:$L$799,0)+399),"") -> 0 | D8: =IFERROR(INDEX($I:$I,MATCH(1,$L$400:$L$799,0)+399),"") -> En cours | F8: =IFERROR(INDEX($A:$A,MATCH($L$799+1,$L$800:$L$1199,0)+799),"") -> TR163 | G8: =IFERROR(INDEX($B:$B,MATCH($L$799+1,$L$800:$L$1199,0)+799),"") -> Rhoea Thornshaw | H8: =IFERROR(INDEX($H:$H,MATCH($L$799+1,$L$800:$L$1199,0)+799),"") | I8: =IFERROR(INDEX($I:$I,MATCH($L$799+1,$L$800:$L$1199,0)+799),"") -> En cours | K8: =IFERROR(INDEX($A:$A,MATCH($L$1199+1,$L$1200:$L$1599,0)+1199),"") -> TR140 | L8: =IFERROR(INDEX($B:$B,MATCH($L$1199+1,$L$1200:$L$1599,0)+1199),"") -> Kelen Toric | M8: =IFERROR(INDEX($H:$H,MATCH($L$1199+1,$L$1200:$L$1599,0)+1199),"") -> 0 | N8: =IFERROR(INDEX($I:$I,MATCH($L$1199+1,$L$1200:$L$1599,0)+1199),"") -> En cours
A9: =IFERROR(INDEX($A:$A,MATCH(2,$L$400:$L$799,0)+399),"") -> TR164 | B9: =IFERROR(INDEX($B:$B,MATCH(2,$L$400:$L$799,0)+399),"") -> Weson Pykefield | C9: =IFERROR(INDEX($H:$H,MATCH(2,$L$400:$L$799,0)+399),"") -> 6 | D9: =IFERROR(INDEX($I:$I,MATCH(2,$L$400:$L$799,0)+399),"") -> En cours | F9: =IFERROR(INDEX($A:$A,MATCH($L$799+2,$L$800:$L$1199,0)+799),"") -> TR164 | G9: =IFERROR(INDEX($B:$B,MATCH($L$799+2,$L$800:$L$1199,0)+799),"") -> Weson Pykefield | H9: =IFERROR(INDEX($H:$H,MATCH($L$799+2,$L$800:$L$1199,0)+799),"") | I9: =IFERROR(INDEX($I:$I,MATCH($L$799+2,$L$800:$L$1199,0)+799),"") -> En cours | K9: =IFERROR(INDEX($A:$A,MATCH($L$1199+2,$L$1200:$L$1599,0)+1199),"") -> TR164 | L9: =IFERROR(INDEX($B:$B,MATCH($L$1199+2,$L$1200:$L$1599,0)+1199),"") -> Weson Pykefield | M9: =IFERROR(INDEX($H:$H,MATCH($L$1199+2,$L$1200:$L$1599,0)+1199),"") | N9: =IFERROR(INDEX($I:$I,MATCH($L$1199+2,$L$1200:$L$1599,0)+1199),"") -> À venir
A10: =IFERROR(INDEX($A:$A,MATCH(3,$L$400:$L$799,0)+399),"") -> TR165 | B10: =IFERROR(INDEX($B:$B,MATCH(3,$L$400:$L$799,0)+399),"") -> Holtmont Rhous Dorum | C10: =IFERROR(INDEX($H:$H,MATCH(3,$L$400:$L$799,0)+399),"") -> 7 | D10: =IFERROR(INDEX($I:$I,MATCH(3,$L$400:$L$799,0)+399),"") -> En cours | F10: =IFERROR(INDEX($A:$A,MATCH($L$799+3,$L$800:$L$1199,0)+799),"") | G10: =IFERROR(INDEX($B:$B,MATCH($L$799+3,$L$800:$L$1199,0)+799),"") | H10: =IFERROR(INDEX($H:$H,MATCH($L$799+3,$L$800:$L$1199,0)+799),"") | I10: =IFERROR(INDEX($I:$I,MATCH($L$799+3,$L$800:$L$1199,0)+799),"") | K10: =IFERROR(INDEX($A:$A,MATCH($L$1199+3,$L$1200:$L$1599,0)+1199),"") | L10: =IFERROR(INDEX($B:$B,MATCH($L$1199+3,$L$1200:$L$1599,0)+1199),"") | M10: =IFERROR(INDEX($H:$H,MATCH($L$1199+3,$L$1200:$L$1599,0)+1199),"") | N10: =IFERROR(INDEX($I:$I,MATCH($L$1199+3,$L$1200:$L$1599,0)+1199),"")
A11: =IFERROR(INDEX($A:$A,MATCH(4,$L$400:$L$799,0)+399),"") -> TR166 | B11: =IFERROR(INDEX($B:$B,MATCH(4,$L$400:$L$799,0)+399),"") -> Norwood Torol Holtridge Ivermont | C11: =IFERROR(INDEX($H:$H,MATCH(4,$L$400:$L$799,0)+399),"") -> 7 | D11: =IFERROR(INDEX($I:$I,MATCH(4,$L$400:$L$799,0)+399),"") -> En cours | F11: =IFERROR(INDEX($A:$A,MATCH($L$799+4,$L$800:$L$1199,0)+799),"") | G11: =IFERROR(INDEX($B:$B,MATCH($L$799+4,$L$800:$L$1199,0)+799),"") | H11: =IFERROR(INDEX($H:$H,MATCH($L$799+4,$L$800:$L$1199,0)+799),"") | I11: =IFERROR(INDEX($I:$I,MATCH($L$799+4,$L$800:$L$1199,0)+799),"") | K11: =IFERROR(INDEX($A:$A,MATCH($L$1199+4,$L$1200:$L$1599,0)+1199),"") | L11: =IFERROR(INDEX($B:$B,MATCH($L$1199+4,$L$1200:$L$1599,0)+1199),"") | M11: =IFERROR(INDEX($H:$H,MATCH($L$1199+4,$L$1200:$L$1599,0)+1199),"") | N11: =IFERROR(INDEX($I:$I,MATCH($L$1199+4,$L$1200:$L$1599,0)+1199),"")
A12: =IFERROR(INDEX($A:$A,MATCH(5,$L$400:$L$799,0)+399),"") -> TR167 | B12: =IFERROR(INDEX($B:$B,MATCH(5,$L$400:$L$799,0)+399),"") -> Wesil Orinen | C12: =IFERROR(INDEX($H:$H,MATCH(5,$L$400:$L$799,0)+399),"") -> 7 | D12: =IFERROR(INDEX($I:$I,MATCH(5,$L$400:$L$799,0)+399),"") -> En cours | F12: =IFERROR(INDEX($A:$A,MATCH($L$799+5,$L$800:$L$1199,0)+799),"") | G12: =IFERROR(INDEX($B:$B,MATCH($L$799+5,$L$800:$L$1199,0)+799),"") | H12: =IFERROR(INDEX($H:$H,MATCH($L$799+5,$L$800:$L$1199,0)+799),"") | I12: =IFERROR(INDEX($I:$I,MATCH($L$799+5,$L$800:$L$1199,0)+799),"") | K12: =IFERROR(INDEX($A:$A,MATCH($L$1199+5,$L$1200:$L$1599,0)+1199),"") | L12: =IFERROR(INDEX($B:$B,MATCH($L$1199+5,$L$1200:$L$1599,0)+1199),"") | M12: =IFERROR(INDEX($H:$H,MATCH($L$1199+5,$L$1200:$L$1599,0)+1199),"") | N12: =IFERROR(INDEX($I:$I,MATCH($L$1199+5,$L$1200:$L$1599,0)+1199),"")
A13: =IFERROR(INDEX($A:$A,MATCH(6,$L$400:$L$799,0)+399),"") -> TR168 | B13: =IFERROR(INDEX($B:$B,MATCH(6,$L$400:$L$799,0)+399),"") -> Ashwood Zanay | C13: =IFERROR(INDEX($H:$H,MATCH(6,$L$400:$L$799,0)+399),"") -> 7 | D13: =IFERROR(INDEX($I:$I,MATCH(6,$L$400:$L$799,0)+399),"") -> En cours | F13: =IFERROR(INDEX($A:$A,MATCH($L$799+6,$L$800:$L$1199,0)+799),"") | G13: =IFERROR(INDEX($B:$B,MATCH($L$799+6,$L$800:$L$1199,0)+799),"") | H13: =IFERROR(INDEX($H:$H,MATCH($L$799+6,$L$800:$L$1199,0)+799),"") | I13: =IFERROR(INDEX($I:$I,MATCH($L$799+6,$L$800:$L$1199,0)+799),"") | K13: =IFERROR(INDEX($A:$A,MATCH($L$1199+6,$L$1200:$L$1599,0)+1199),"") | L13: =IFERROR(INDEX($B:$B,MATCH($L$1199+6,$L$1200:$L$1599,0)+1199),"") | M13: =IFERROR(INDEX($H:$H,MATCH($L$1199+6,$L$1200:$L$1599,0)+1199),"") | N13: =IFERROR(INDEX($I:$I,MATCH($L$1199+6,$L$1200:$L$1599,0)+1199),"")
A14: =IFERROR(INDEX($A:$A,MATCH(7,$L$400:$L$799,0)+399),"") -> TR169 | B14: =IFERROR(INDEX($B:$B,MATCH(7,$L$400:$L$799,0)+399),"") -> Dorel Wrenhaven | C14: =IFERROR(INDEX($H:$H,MATCH(7,$L$400:$L$799,0)+399),"") -> 7 | D14: =IFERROR(INDEX($I:$I,MATCH(7,$L$400:$L$799,0)+399),"") -> En cours | F14: =IFERROR(INDEX($A:$A,MATCH($L$799+7,$L$800:$L$1199,0)+799),"") | G14: =IFERROR(INDEX($B:$B,MATCH($L$799+7,$L$800:$L$1199,0)+799),"") | H14: =IFERROR(INDEX($H:$H,MATCH($L$799+7,$L$800:$L$1199,0)+799),"") | I14: =IFERROR(INDEX($I:$I,MATCH($L$799+7,$L$800:$L$1199,0)+799),"") | K14: =IFERROR(INDEX($A:$A,MATCH($L$1199+7,$L$1200:$L$1599,0)+1199),"") | L14: =IFERROR(INDEX($B:$B,MATCH($L$1199+7,$L$1200:$L$1599,0)+1199),"") | M14: =IFERROR(INDEX($H:$H,MATCH($L$1199+7,$L$1200:$L$1599,0)+1199),"") | N14: =IFERROR(INDEX($I:$I,MATCH($L$1199+7,$L$1200:$L$1599,0)+1199),"")
A15: =IFERROR(INDEX($A:$A,MATCH(8,$L$400:$L$799,0)+399),"") -> TR170 | B15: =IFERROR(INDEX($B:$B,MATCH(8,$L$400:$L$799,0)+399),"") -> Moril Wesus Wrenfield | C15: =IFERROR(INDEX($H:$H,MATCH(8,$L$400:$L$799,0)+399),"") -> 7 | D15: =IFERROR(INDEX($I:$I,MATCH(8,$L$400:$L$799,0)+399),"") -> En cours | F15: =IFERROR(INDEX($A:$A,MATCH($L$799+8,$L$800:$L$1199,0)+799),"") | G15: =IFERROR(INDEX($B:$B,MATCH($L$799+8,$L$800:$L$1199,0)+799),"") | H15: =IFERROR(INDEX($H:$H,MATCH($L$799+8,$L$800:$L$1199,0)+799),"") | I15: =IFERROR(INDEX($I:$I,MATCH($L$799+8,$L$800:$L$1199,0)+799),"") | K15: =IFERROR(INDEX($A:$A,MATCH($L$1199+8,$L$1200:$L$1599,0)+1199),"") | L15: =IFERROR(INDEX($B:$B,MATCH($L$1199+8,$L$1200:$L$1599,0)+1199),"") | M15: =IFERROR(INDEX($H:$H,MATCH($L$1199+8,$L$1200:$L$1599,0)+1199),"") | N15: =IFERROR(INDEX($I:$I,MATCH($L$1199+8,$L$1200:$L$1599,0)+1199),"")
A16: =IFERROR(INDEX($A:$A,MATCH(9,$L$400:$L$799,0)+399),"") -> TR171 | B16: =IFERROR(INDEX($B:$B,MATCH(9,$L$400:$L$799,0)+399),"") -> Zanan Pelol | C16: =IFERROR(INDEX($H:$H,MATCH(9,$L$400:$L$799,0)+399),"") -> 7 | D16: =IFERROR(INDEX($I:$I,MATCH(9,$L$400:$L$799,0)+399),"") -> En cours | F16: =IFERROR(INDEX($A:$A,MATCH($L$799+9,$L$800:$L$1199,0)+799),"") | G16: =IFERROR(INDEX($B:$B,MATCH($L$799+9,$L$800:$L$1199,0)+799),"") | H16: =IFERROR(INDEX($H:$H,MATCH($L$799+9,$L$800:$L$1199,0)+799),"") | I16: =IFERROR(INDEX($I:$I,MATCH($L$799+9,$L$800:$L$1199,0)+799),"") | K16: =IFERROR(INDEX($A:$A,MATCH($L$1199+9,$L$1200:$L$1599,0)+1199),"") | L16: =IFERROR(INDEX($B:$B,MATCH($L$1199+9,$L$1200:$L$1599,0)+1199),"") | M16: =IFERROR(INDEX($H:$H,MATCH($L$1199+9,$L$1200:$L$1599,0)+1199),"") | N16: =IFERROR(INDEX($I:$I,MATCH($L$1199+9,$L$1200:$L$1599,0)+1199),"")
A17: =IFERROR(INDEX($A:$A,MATCH(10,$L$400:$L$799,0)+399),"") -> TR172 | B17: =IFERROR(INDEX($B:$B,MATCH(10,$L$400:$L$799,0)+399),"") -> Ashmont Kendwood | C17: =IFERROR(INDEX($H:$H,MATCH(10,$L$400:$L$799,0)+399),"") -> 7 | D17: =IFERROR(INDEX($I:$I,MATCH(10,$L$400:$L$799,0)+399),"") -> En cours | F17: =IFERROR(INDEX($A:$A,MATCH($L$799+10,$L$800:$L$1199,0)+799),"") | G17: =IFERROR(INDEX($B:$B,MATCH($L$799+10,$L$800:$L$1199,0)+799),"") | H17: =IFERROR(INDEX($H:$H,MATCH($L$799+10,$L$800:$L$1199,0)+799),"") | I17: =IFERROR(INDEX($I:$I,MATCH($L$799+10,$L$800:$L$1199,0)+799),"") | K17: =IFERROR(INDEX($A:$A,MATCH($L$1199+10,$L$1200:$L$1599,0)+1199),"") | L17: =IFERROR(INDEX($B:$B,MATCH($L$1199+10,$L$1200:$L$1599,0)+1199),"") | M17: =IFERROR(INDEX($H:$H,MATCH($L$1199+10,$L$1200:$L$1599,0)+1199),"") | N17: =IFERROR(INDEX($I:$I,MATCH($L$1199+10,$L$1200:$L$1599,0)+1199),"")
A18: =IFERROR(INDEX($A:$A,MATCH(11,$L$400:$L$799,0)+399),"") -> TR173 | B18: =IFERROR(INDEX($B:$B,MATCH(11,$L$400:$L$799,0)+399),"") -> Marsmont Wesan | C18: =IFERROR(INDEX($H:$H,MATCH(11,$L$400:$L$799,0)+399),"") -> 7 | D18: =IFERROR(INDEX($I:$I,MATCH(11,$L$400:$L$799,0)+399),"") -> En cours | F18: =IFERROR(INDEX($A:$A,MATCH($L$799+11,$L$800:$L$1199,0)+799),"") | G18: =IFERROR(INDEX($B:$B,MATCH($L$799+11,$L$800:$L$1199,0)+799),"") | H18: =IFERROR(INDEX($H:$H,MATCH($L$799+11,$L$800:$L$1199,0)+799),"") | I18: =IFERROR(INDEX($I:$I,MATCH($L$799+11,$L$800:$L$1199,0)+799),"") | K18: =IFERROR(INDEX($A:$A,MATCH($L$1199+11,$L$1200:$L$1599,0)+1199),"") | L18: =IFERROR(INDEX($B:$B,MATCH($L$1199+11,$L$1200:$L$1599,0)+1199),"") | M18: =IFERROR(INDEX($H:$H,MATCH($L$1199+11,$L$1200:$L$1599,0)+1199),"") | N18: =IFERROR(INDEX($I:$I,MATCH($L$1199+11,$L$1200:$L$1599,0)+1199),"")
A19: =IFERROR(INDEX($A:$A,MATCH(12,$L$400:$L$799,0)+399),"") -> TR174 | B19: =IFERROR(INDEX($B:$B,MATCH(12,$L$400:$L$799,0)+399),"") -> Lumon Quillcroft Stelridge Gilus | C19: =IFERROR(INDEX($H:$H,MATCH(12,$L$400:$L$799,0)+399),"") -> 7 | D19: =IFERROR(INDEX($I:$I,MATCH(12,$L$400:$L$799,0)+399),"") -> En cours | F19: =IFERROR(INDEX($A:$A,MATCH($L$799+12,$L$800:$L$1199,0)+799),"") | G19: =IFERROR(INDEX($B:$B,MATCH($L$799+12,$L$800:$L$1199,0)+799),"") | H19: =IFERROR(INDEX($H:$H,MATCH($L$799+12,$L$800:$L$1199,0)+799),"") | I19: =IFERROR(INDEX($I:$I,MATCH($L$799+12,$L$800:$L$1199,0)+799),"") | K19: =IFERROR(INDEX($A:$A,MATCH($L$1199+12,$L$1200:$L$1599,0)+1199),"") | L19: =IFERROR(INDEX($B:$B,MATCH($L$1199+12,$L$1200:$L$1599,0)+1199),"") | M19: =IFERROR(INDEX($H:$H,MATCH($L$1199+12,$L$1200:$L$1599,0)+1199),"") | N19: =IFERROR(INDEX($I:$I,MATCH($L$1199+12,$L$1200:$L$1599,0)+1199),"")
A20: =IFERROR(INDEX($A:$A,MATCH(13,$L$400:$L$799,0)+399),"") -> TR175 | B20: =IFERROR(INDEX($B:$B,MATCH(13,$L$400:$L$799,0)+399),"") -> Gilor Stelbrook | C20: =IFERROR(INDEX($H:$H,MATCH(13,$L$400:$L$799,0)+399),"") -> 7 | D20: =IFERROR(INDEX($I:$I,MATCH(13,$L$400:$L$799,0)+399),"") -> En cours | F20: =IFERROR(INDEX($A:$A,MATCH($L$799+13,$L$800:$L$1199,0)+799),"") | G20: =IFERROR(INDEX($B:$B,MATCH($L$799+13,$L$800:$L$1199,0)+799),"") | H20: =IFERROR(INDEX($H:$H,MATCH($L$799+13,$L$800:$L$1199,0)+799),"") | I20: =IFERROR(INDEX($I:$I,MATCH($L$799+13,$L$800:$L$1199,0)+799),"") | K20: =IFERROR(INDEX($A:$A,MATCH($L$1199+13,$L$1200:$L$1599,0)+1199),"") | L20: =IFERROR(INDEX($B:$B,MATCH($L$1199+13,$L$1200:$L$1599,0)+1199),"") | M20: =IFERROR(INDEX($H:$H,MATCH($L$1199+13,$L$1200:$L$1599,0)+1199),"") | N20: =IFERROR(INDEX($I:$I,MATCH($L$1199+13,$L$1200:$L$1599,0)+1199),"")
A21: =IFERROR(INDEX($A:$A,MATCH(14,$L$400:$L$799,0)+399),"") -> TR176 | B21: =IFERROR(INDEX($B:$B,MATCH(14,$L$400:$L$799,0)+399),"") -> Rhoic Iverstone | C21: =IFERROR(INDEX($H:$H,MATCH(14,$L$400:$L$799,0)+399),"") -> 7 | D21: =IFERROR(INDEX($I:$I,MATCH(14,$L$400:$L$799,0)+399),"") -> En cours | F21: =IFERROR(INDEX($A:$A,MATCH($L$799+14,$L$800:$L$1199,0)+799),"") | G21: =IFERROR(INDEX($B:$B,MATCH($L$799+14,$L$800:$L$1199,0)+799),"") | H21: =IFERROR(INDEX($H:$H,MATCH($L$799+14,$L$800:$L$1199,0)+799),"") | I21: =IFERROR(INDEX($I:$I,MATCH($L$799+14,$L$800:$L$1199,0)+799),"") | K21: =IFERROR(INDEX($A:$A,MATCH($L$1199+14,$L$1200:$L$1599,0)+1199),"") | L21: =IFERROR(INDEX($B:$B,MATCH($L$1199+14,$L$1200:$L$1599,0)+1199),"") | M21: =IFERROR(INDEX($H:$H,MATCH($L$1199+14,$L$1200:$L$1599,0)+1199),"") | N21: =IFERROR(INDEX($I:$I,MATCH($L$1199+14,$L$1200:$L$1599,0)+1199),"")
A22: =IFERROR(INDEX($A:$A,MATCH(15,$L$400:$L$799,0)+399),"") -> TR177 | B22: =IFERROR(INDEX($B:$B,MATCH(15,$L$400:$L$799,0)+399),"") -> Corrfield Haxay Quenen | C22: =IFERROR(INDEX($H:$H,MATCH(15,$L$400:$L$799,0)+399),"") -> 7 | D22: =IFERROR(INDEX($I:$I,MATCH(15,$L$400:$L$799,0)+399),"") -> En cours | F22: =IFERROR(INDEX($A:$A,MATCH($L$799+15,$L$800:$L$1199,0)+799),"") | G22: =IFERROR(INDEX($B:$B,MATCH($L$799+15,$L$800:$L$1199,0)+799),"") | H22: =IFERROR(INDEX($H:$H,MATCH($L$799+15,$L$800:$L$1199,0)+799),"") | I22: =IFERROR(INDEX($I:$I,MATCH($L$799+15,$L$800:$L$1199,0)+799),"") | K22: =IFERROR(INDEX($A:$A,MATCH($L$1199+15,$L$1200:$L$1599,0)+1199),"") | L22: =IFERROR(INDEX($B:$B,MATCH($L$1199+15,$L$1200:$L$1599,0)+1199),"") | M22: =IFERROR(INDEX($H:$H,MATCH($L$1199+15,$L$1200:$L$1599,0)+1199),"") | N22: =IFERROR(INDEX($I:$I,MATCH($L$1199+15,$L$1200:$L$1599,0)+1199),"")
A23: =IFERROR(INDEX($A:$A,MATCH(16,$L$400:$L$799,0)+399),"") | B23: =IFERROR(INDEX($B:$B,MATCH(16,$L$400:$L$799,0)+399),"") | C23: =IFERROR(INDEX($H:$H,MATCH(16,$L$400:$L$799,0)+399),"") | D23: =IFERROR(INDEX($I:$I,MATCH(16,$L$400:$L$799,0)+399),"") | F23: =IFERROR(INDEX($A:$A,MATCH($L$799+16,$L$800:$L$1199,0)+799),"") | G23: =IFERROR(INDEX($B:$B,MATCH($L$799+16,$L$800:$L$1199,0)+799),"") | H23: =IFERROR(INDEX($H:$H,MATCH($L$799+16,$L$800:$L$1199,0)+799),"") | I23: =IFERROR(INDEX($I:$I,MATCH($L$799+16,$L$800:$L$1199,0)+799),"") | K23: =IFERROR(INDEX($A:$A,MATCH($L$1199+16,$L$1200:$L$1599,0)+1199),"") | L23: =IFERROR(INDEX($B:$B,MATCH($L$1199+16,$L$1200:$L$1599,0)+1199),"") | M23: =IFERROR(INDEX($H:$H,MATCH($L$1199+16,$L$1200:$L$1599,0)+1199),"") | N23: =IFERROR(INDEX($I:$I,MATCH($L$1199+16,$L$1200:$L$1599,0)+1199),"")
A24: =IFERROR(INDEX($A:$A,MATCH(17,$L$400:$L$799,0)+399),"") | B24: =IFERROR(INDEX($B:$B,MATCH(17,$L$400:$L$799,0)+399),"") | C24: =IFERROR(INDEX($H:$H,MATCH(17,$L$400:$L$799,0)+399),"") | D24: =IFERROR(INDEX($I:$I,MATCH(17,$L$400:$L$799,0)+399),"") | F24: =IFERROR(INDEX($A:$A,MATCH($L$799+17,$L$800:$L$1199,0)+799),"") | G24: =IFERROR(INDEX($B:$B,MATCH($L$799+17,$L$800:$L$1199,0)+799),"") | H24: =IFERROR(INDEX($H:$H,MATCH($L$799+17,$L$800:$L$1199,0)+799),"") | I24: =IFERROR(INDEX($I:$I,MATCH($L$799+17,$L$800:$L$1199,0)+799),"") | K24: =IFERROR(INDEX($A:$A,MATCH($L$1199+17,$L$1200:$L$1599,0)+1199),"") | L24: =IFERROR(INDEX($B:$B,MATCH($L$1199+17,$L$1200:$L$1599,0)+1199),"") | M24: =IFERROR(INDEX($H:$H,MATCH($L$1199+17,$L$1200:$L$1599,0)+1199),"") | N24: =IFERROR(INDEX($I:$I,MATCH($L$1199+17,$L$1200:$L$1599,0)+1199),"")
A25: =IFERROR(INDEX($A:$A,MATCH(18,$L$400:$L$799,0)+399),"") | B25: =IFERROR(INDEX($B:$B,MATCH(18,$L$400:$L$799,0)+399),"") | C25: =IFERROR(INDEX($H:$H,MATCH(18,$L$400:$L$799,0)+399),"") | D25: =IFERROR(INDEX($I:$I,MATCH(18,$L$400:$L$799,0)+399),"") | F25: =IFERROR(INDEX($A:$A,MATCH($L$799+18,$L$800:$L$1199,0)+799),"") | G25: =IFERROR(INDEX($B:$B,MATCH($L$799+18,$L$800:$L$1199,0)+799),"") | H25: =IFERROR(INDEX($H:$H,MATCH($L$799+18,$L$800:$L$1199,0)+799),"") | I25: =IFERROR(INDEX($I:$I,MATCH($L$799+18,$L$800:$L$1199,0)+799),"") | K25: =IFERROR(INDEX($A:$A,MATCH($L$1199+18,$L$1200:$L$1599,0)+1199),"") | L25: =IFERROR(INDEX($B:$B,MATCH($L$1199+18,$L$1200:$L$1599,0)+1199),"") | M25: =IFERROR(INDEX($H:$H,MATCH($L$1199+18,$L$1200:$L$1599,0)+1199),"") | N25: =IFERROR(INDEX($I:$I,MATCH($L$1199+18,$L$1200:$L$1599,0)+1199),"")
A26: =IFERROR(INDEX($A:$A,MATCH(19,$L$400:$L$799,0)+399),"") | B26: =IFERROR(INDEX($B:$B,MATCH(19,$L$400:$L$799,0)+399),"") | C26: =IFERROR(INDEX($H:$H,MATCH(19,$L$400:$L$799,0)+399),"") | D26: =IFERROR(INDEX($I:$I,MATCH(19,$L$400:$L$799,0)+399),"") | F26: =IFERROR(INDEX($A:$A,MATCH($L$799+19,$L$800:$L$1199,0)+799),"") | G26: =IFERROR(INDEX($B:$B,MATCH($L$799+19,$L$800:$L$1199,0)+799),"") | H26: =IFERROR(INDEX($H:$H,MATCH($L$799+19,$L$800:$L$1199,0)+799),"") | I26: =IFERROR(INDEX($I:$I,MATCH($L$799+19,$L$800:$L$1199,0)+799),"") | K26: =IFERROR(INDEX($A:$A,MATCH($L$1199+19,$L$1200:$L$1599,0)+1199),"") | L26: =IFERROR(INDEX($B:$B,MATCH($L$1199+19,$L$1200:$L$1599,0)+1199),"") | M26: =IFERROR(INDEX($H:$H,MATCH($L$1199+19,$L$1200:$L$1599,0)+1199),"") | N26: =IFERROR(INDEX($I:$I,MATCH($L$1199+19,$L$1200:$L$1599,0)+1199),"")
A27: =IFERROR(INDEX($A:$A,MATCH(20,$L$400:$L$799,0)+399),"") | B27: =IFERROR(INDEX($B:$B,MATCH(20,$L$400:$L$799,0)+399),"") | C27: =IFERROR(INDEX($H:$H,MATCH(20,$L$400:$L$799,0)+399),"") | D27: =IFERROR(INDEX($I:$I,MATCH(20,$L$400:$L$799,0)+399),"") | F27: =IFERROR(INDEX($A:$A,MATCH($L$799+20,$L$800:$L$1199,0)+799),"") | G27: =IFERROR(INDEX($B:$B,MATCH($L$799+20,$L$800:$L$1199,0)+799),"") | H27: =IFERROR(INDEX($H:$H,MATCH($L$799+20,$L$800:$L$1199,0)+799),"") | I27: =IFERROR(INDEX($I:$I,MATCH($L$799+20,$L$800:$L$1199,0)+799),"") | K27: =IFERROR(INDEX($A:$A,MATCH($L$1199+20,$L$1200:$L$1599,0)+1199),"") | L27: =IFERROR(INDEX($B:$B,MATCH($L$1199+20,$L$1200:$L$1599,0)+1199),"") | M27: =IFERROR(INDEX($H:$H,MATCH($L$1199+20,$L$1200:$L$1599,0)+1199),"") | N27: =IFERROR(INDEX($I:$I,MATCH($L$1199+20,$L$1200:$L$1599,0)+1199),"")
A28: =IFERROR(INDEX($A:$A,MATCH(21,$L$400:$L$799,0)+399),"") | B28: =IFERROR(INDEX($B:$B,MATCH(21,$L$400:$L$799,0)+399),"") | C28: =IFERROR(INDEX($H:$H,MATCH(21,$L$400:$L$799,0)+399),"") | D28: =IFERROR(INDEX($I:$I,MATCH(21,$L$400:$L$799,0)+399),"") | F28: =IFERROR(INDEX($A:$A,MATCH($L$799+21,$L$800:$L$1199,0)+799),"") | G28: =IFERROR(INDEX($B:$B,MATCH($L$799+21,$L$800:$L$1199,0)+799),"") | H28: =IFERROR(INDEX($H:$H,MATCH($L$799+21,$L$800:$L$1199,0)+799),"") | I28: =IFERROR(INDEX($I:$I,MATCH($L$799+21,$L$800:$L$1199,0)+799),"") | K28: =IFERROR(INDEX($A:$A,MATCH($L$1199+21,$L$1200:$L$1599,0)+1199),"") | L28: =IFERROR(INDEX($B:$B,MATCH($L$1199+21,$L$1200:$L$1599,0)+1199),"") | M28: =IFERROR(INDEX($H:$H,MATCH($L$1199+21,$L$1200:$L$1599,0)+1199),"") | N28: =IFERROR(INDEX($I:$I,MATCH($L$1199+21,$L$1200:$L$1599,0)+1199),"")
A29: =IFERROR(INDEX($A:$A,MATCH(22,$L$400:$L$799,0)+399),"") | B29: =IFERROR(INDEX($B:$B,MATCH(22,$L$400:$L$799,0)+399),"") | C29: =IFERROR(INDEX($H:$H,MATCH(22,$L$400:$L$799,0)+399),"") | D29: =IFERROR(INDEX($I:$I,MATCH(22,$L$400:$L$799,0)+399),"") | F29: =IFERROR(INDEX($A:$A,MATCH($L$799+22,$L$800:$L$1199,0)+799),"") | G29: =IFERROR(INDEX($B:$B,MATCH($L$799+22,$L$800:$L$1199,0)+799),"") | H29: =IFERROR(INDEX($H:$H,MATCH($L$799+22,$L$800:$L$1199,0)+799),"") | I29: =IFERROR(INDEX($I:$I,MATCH($L$799+22,$L$800:$L$1199,0)+799),"") | K29: =IFERROR(INDEX($A:$A,MATCH($L$1199+22,$L$1200:$L$1599,0)+1199),"") | L29: =IFERROR(INDEX($B:$B,MATCH($L$1199+22,$L$1200:$L$1599,0)+1199),"") | M29: =IFERROR(INDEX($H:$H,MATCH($L$1199+22,$L$1200:$L$1599,0)+1199),"") | N29: =IFERROR(INDEX($I:$I,MATCH($L$1199+22,$L$1200:$L$1599,0)+1199),"")
A30: =IFERROR(INDEX($A:$A,MATCH(23,$L$400:$L$799,0)+399),"") | B30: =IFERROR(INDEX($B:$B,MATCH(23,$L$400:$L$799,0)+399),"") | C30: =IFERROR(INDEX($H:$H,MATCH(23,$L$400:$L$799,0)+399),"") | D30: =IFERROR(INDEX($I:$I,MATCH(23,$L$400:$L$799,0)+399),"") | F30: =IFERROR(INDEX($A:$A,MATCH($L$799+23,$L$800:$L$1199,0)+799),"") | G30: =IFERROR(INDEX($B:$B,MATCH($L$799+23,$L$800:$L$1199,0)+799),"") | H30: =IFERROR(INDEX($H:$H,MATCH($L$799+23,$L$800:$L$1199,0)+799),"") | I30: =IFERROR(INDEX($I:$I,MATCH($L$799+23,$L$800:$L$1199,0)+799),"") | K30: =IFERROR(INDEX($A:$A,MATCH($L$1199+23,$L$1200:$L$1599,0)+1199),"") | L30: =IFERROR(INDEX($B:$B,MATCH($L$1199+23,$L$1200:$L$1599,0)+1199),"") | M30: =IFERROR(INDEX($H:$H,MATCH($L$1199+23,$L$1200:$L$1599,0)+1199),"") | N30: =IFERROR(INDEX($I:$I,MATCH($L$1199+23,$L$1200:$L$1599,0)+1199),"")
A31: =IFERROR(INDEX($A:$A,MATCH(24,$L$400:$L$799,0)+399),"") | B31: =IFERROR(INDEX($B:$B,MATCH(24,$L$400:$L$799,0)+399),"") | C31: =IFERROR(INDEX($H:$H,MATCH(24,$L$400:$L$799,0)+399),"") | D31: =IFERROR(INDEX($I:$I,MATCH(24,$L$400:$L$799,0)+399),"") | F31: =IFERROR(INDEX($A:$A,MATCH($L$799+24,$L$800:$L$1199,0)+799),"") | G31: =IFERROR(INDEX($B:$B,MATCH($L$799+24,$L$800:$L$1199,0)+799),"") | H31: =IFERROR(INDEX($H:$H,MATCH($L$799+24,$L$800:$L$1199,0)+799),"") | I31: =IFERROR(INDEX($I:$I,MATCH($L$799+24,$L$800:$L$1199,0)+799),"") | K31: =IFERROR(INDEX($A:$A,MATCH($L$1199+24,$L$1200:$L$1599,0)+1199),"") | L31: =IFERROR(INDEX($B:$B,MATCH($L$1199+24,$L$1200:$L$1599,0)+1199),"") | M31: =IFERROR(INDEX($H:$H,MATCH($L$1199+24,$L$1200:$L$1599,0)+1199),"") | N31: =IFERROR(INDEX($I:$I,MATCH($L$1199+24,$L$1200:$L$1599,0)+1199),"")
A399: HELPER (do not edit)
A400: =IF('Formation Initiale'!$A2="","",'Formation Initiale'!$A2) -> TR129 | B400: =IF($A400="","",'Formation Initiale'!$E2) -> Haxil Dellhaven | C400: =IF($A400="","",'Formation Initiale'!$F2) -> Lisbonne | D400: =IF($A400="","",IF('Formation Initiale'!$F2="Lisbonne","B2C (Initiale)","B2C+B2B (Initiale)")) -> B2C (Initiale) | E400: =IF($A400="","",'Formation Initiale'!$B2) -> OS1 | F400: =IF($A400="","",'Formation Initiale'!$G2) -> 46006 | G400: =IF($A400="","",'Formation Initiale'!$H2) -> 46017 | H400: =IF($A400="","",'Formation Initiale'!$L2) -> 0 | I400: =IF($A400="","",'Formation Initiale'!$R2) -> Terminé | K400: =IF(A400="",0,IF(IFERROR(VLOOKUP(A400,Skills!$A:$M,13,FALSE()),"")="COS",0,IF(OR(I400="En cours",I400="À venir",I400="À planifier"),IF(AND(OR($C$3="Tous",$C$3="",C400=$C$3),OR($E$3="Tous",$E$3="",I400=$E$3)),1,0),0))) -> 0 | L400: =K400 -> 0
A401: =IF('Formation Initiale'!$A3="","",'Formation Initiale'!$A3) -> TR099 | B401: =IF($A401="","",'Formation Initiale'!$E3) -> Haxay Corrfield Dellstone | C401: =IF($A401="","",'Formation Initiale'!$F3) -> Lisbonne | D401: =IF($A401="","",IF('Formation Initiale'!$F3="Lisbonne","B2C (Initiale)","B2C+B2B (Initiale)")) -> B2C (Initiale) | E401: =IF($A401="","",'Formation Initiale'!$B3) -> OS1 | F401: =IF($A401="","",'Formation Initiale'!$G3) -> 46006 | G401: =IF($A401="","",'Formation Initiale'!$H3) -> 46017 | H401: =IF($A401="","",'Formation Initiale'!$L3) -> 0 | I401: =IF($A401="","",'Formation Initiale'!$R3) -> Terminé | K401: =IF(A401="",0,IF(IFERROR(VLOOKUP(A401,Skills!$A:$M,13,FALSE()),"")="COS",0,IF(OR(I401="En cours",I401="À venir",I401="À planifier"),IF(AND(OR($C$3="Tous",$C$3="",C401=$C$3),OR($E$3="Tous",$E$3="",I401=$E$3)),1,0),0))) -> 0 | L401: =L400+K401 -> 0
A402: =IF('Formation Initiale'!$A4="","",'Formation Initiale'!$A4) -> TR021 | B402: =IF($A402="","",'Formation Initiale'!$E4) -> Nevus Kelir | C402: =IF($A402="","",'Formation Initiale'!$F4) -> Lisbonne | D402: =IF($A402="","",IF('Formation Initiale'!$F4="Lisbonne","B2C (Initiale)","B2C+B2B (Initiale)")) -> B2C (Initiale) | E402: =IF($A402="","",'Formation Initiale'!$B4) -> OS1 | F402: =IF($A402="","",'Formation Initiale'!$G4) -> 46006 | G402: =IF($A402="","",'Formation Initiale'!$H4) -> 46017 | H402: =IF($A402="","",'Formation Initiale'!$L4) -> 0 | I402: =IF($A402="","",'Formation Initiale'!$R4) -> Terminé | K402: =IF(A402="",0,IF(IFERROR(VLOOKUP(A402,Skills!$A:$M,13,FALSE()),"")="COS",0,IF(OR(I402="En cours",I402="À venir",I402="À planifier"),IF(AND(OR($C$3="Tous",$C$3="",C402=$C$3),OR($E$3="Tous",$E$3="",I402=$E$3)),1,0),0))) -> 0 | L402: =L401+K402 -> 0
A403: =IF('Formation Initiale'!$A5="","",'Formation Initiale'!$A5) -> TR018 | B403: =IF($A403="","",'Formation Initiale'!$E5) -> Granbrook Yoril Corrfield | C403: =IF($A403="","",'Formation Initiale'!$F5) -> Lisbonne | D403: =IF($A403="","",IF('Formation Initiale'!$F5="Lisbonne","B2C (Initiale)","B2C+B2B (Initiale)")) -> B2C (Initiale) | E403: =IF($A403="","",'Formation Initiale'!$B5) -> OS1 | F403: =IF($A403="","",'Formation Initiale'!$G5) -> 46006 | G403: =IF($A403="","",'Formation Initiale'!$H5) -> 46017 | H403: =IF($A403="","",'Formation Initiale'!$L5) -> 0 | I403: =IF($A403="","",'Formation Initiale'!$R5) -> Terminé | K403: =IF(A403="",0,IF(IFERROR(VLOOKUP(A403,Skills!$A:$M,13,FALSE()),"")="COS",0,IF(OR(I403="En cours",I403="À venir",I403="À planifier"),IF(AND(OR($C$3="Tous",$C$3="",C403=$C$3),OR($E$3="Tous",$E$3="",I403=$E$3)),1,0),0))) -> 0 | L403: =L402+K403 -> 0
A404: =IF('Formation Initiale'!$A6="","",'Formation Initiale'!$A6) -> TR093 | B404: =IF($A404="","",'Formation Initiale'!$E6) -> Holtshaw Haxor | C404: =IF($A404="","",'Formation Initiale'!$F6) -> Lisbonne | D404: =IF($A404="","",IF('Formation Initiale'!$F6="Lisbonne","B2C (Initiale)","B2C+B2B (Initiale)")) -> B2C (Initiale) | E404: =IF($A404="","",'Formation Initiale'!$B6) -> OS1 | F404: =IF($A404="","",'Formation Initiale'!$G6) -> 46006 | G404: =IF($A404="","",'Formation Initiale'!$H6) -> 46017 | H404: =IF($A404="","",'Formation Initiale'!$L6) -> 0 | I404: =IF($A404="","",'Formation Initiale'!$R6) -> Terminé | K404: =IF(A404="",0,IF(IFERROR(VLOOKUP(A404,Skills!$A:$M,13,FALSE()),"")="COS",0,IF(OR(I404="En cours",I404="À venir",I404="À planifier"),IF(AND(OR($C$3="Tous",$C$3="",C404=$C$3),OR($E$3="Tous",$E$3="",I404=$E$3)),1,0),0))) -> 0 | L404: =L403+K404 -> 0
A405: =IF('Formation Initiale'!$A7="","",'Formation Initiale'!$A7) -> TR100 | B405: =IF($A405="","",'Formation Initiale'!$E7) -> Ashdale Valedale | C405: =IF($A405="","",'Formation Initiale'!$F7) -> Lisbonne | D405: =IF($A405="","",IF('Formation Initiale'!$F7="Lisbonne","B2C (Initiale)","B2C+B2B (Initiale)")) -> B2C (Initiale) | E405: =IF($A405="","",'Formation Initiale'!$B7) -> OS1 | F405: =IF($A405="","",'Formation Initiale'!$G7) -> 46006 | G405: =IF($A405="","",'Formation Initiale'!$H7) -> 46017 | H405: =IF($A405="","",'Formation Initiale'!$L7) -> 0 | I405: =IF($A405="","",'Formation Initiale'!$R7) -> Terminé | K405: =IF(A405="",0,IF(IFERROR(VLOOKUP(A405,Skills!$A:$M,13,FALSE()),"")="COS",0,IF(OR(I405="En cours",I405="À venir",I405="À planifier"),IF(AND(OR($C$3="Tous",$C$3="",C405=$C$3),OR($E$3="Tous",$E$3="",I405=$E$3)),1,0),0))) -> 0 | L405: =L404+K405 -> 0
A406: =IF('Formation Initiale'!$A8="","",'Formation Initiale'!$A8) -> TR051 | B406: =IF($A406="","",'Formation Initiale'!$E8) -> Ashcroft Pelan | C406: =IF($A406="","",'Formation Initiale'!$F8) -> Lisbonne | D406: =IF($A406="","",IF('Formation Initiale'!$F8="Lisbonne","B2C (Initiale)","B2C+B2B (Initiale)")) -> B2C (Initiale) | E406: =IF($A406="","",'Formation Initiale'!$B8) -> OS1 | F406: =IF($A406="","",'Formation Initiale'!$G8) -> 46006 | G406: =IF($A406="","",'Formation Initiale'!$H8) -> 46017 | H406: =IF($A406="","",'Formation Initiale'!$L8) -> 0 | I406: =IF($A406="","",'Formation Initiale'!$R8) -> Terminé | K406: =IF(A406="",0,IF(IFERROR(VLOOKUP(A406,Skills!$A:$M,13,FALSE()),"")="COS",0,IF(OR(I406="En cours",I406="À venir",I406="À planifier"),IF(AND(OR($C$3="Tous",$C$3="",C406=$C$3),OR($E$3="Tous",$E$3="",I406=$E$3)),1,0),0))) -> 0 | L406: =L405+K406 -> 0
A407: =IF('Formation Initiale'!$A9="","",'Formation Initiale'!$A9) -> TR122 | B407: =IF($A407="","",'Formation Initiale'!$E9) -> Wrendale Wesum | C407: =IF($A407="","",'Formation Initiale'!$F9) -> Lisbonne | D407: =IF($A407="","",IF('Formation Initiale'!$F9="Lisbonne","B2C (Initiale)","B2C+B2B (Initiale)")) -> B2C (Initiale) | E407: =IF($A407="","",'Formation Initiale'!$B9) -> OS1 | F407: =IF($A407="","",'Formation Initiale'!$G9) -> 46006 | G407: =IF($A407="","",'Formation Initiale'!$H9) -> 46017 | H407: =IF($A407="","",'Formation Initiale'!$L9) -> 0 | I407: =IF($A407="","",'Formation Initiale'!$R9) -> Terminé | K407: =IF(A407="",0,IF(IFERROR(VLOOKUP(A407,Skills!$A:$M,13,FALSE()),"")="COS",0,IF(OR(I407="En cours",I407="À venir",I407="À planifier"),IF(AND(OR($C$3="Tous",$C$3="",C407=$C$3),OR($E$3="Tous",$E$3="",I407=$E$3)),1,0),0))) -> 0 | L407: =L406+K407 -> 0
A408: =IF('Formation Initiale'!$A10="","",'Formation Initiale'!$A10) -> TR073 | B408: =IF($A408="","",'Formation Initiale'!$E10) -> Brammont Holtvale | C408: =IF($A408="","",'Formation Initiale'!$F10) -> Lisbonne | D408: =IF($A408="","",IF('Formation Initiale'!$F10="Lisbonne","B2C (Initiale)","B2C+B2B (Initiale)")) -> B2C (Initiale) | E408: =IF($A408="","",'Formation Initiale'!$B10) -> OS1 | F408: =IF($A408="","",'Formation Initiale'!$G10) -> 46006 | G408: =IF($A408="","",'Formation Initiale'!$H10) -> 46017 | H408: =IF($A408="","",'Formation Initiale'!$L10) -> 0 | I408: =IF($A408="","",'Formation Initiale'!$R10) -> Terminé | K408: =IF(A408="",0,IF(IFERROR(VLOOKUP(A408,Skills!$A:$M,13,FALSE()),"")="COS",0,IF(OR(I408="En cours",I408="À venir",I408="À planifier"),IF(AND(OR($C$3="Tous",$C$3="",C408=$C$3),OR($E$3="Tous",$E$3="",I408=$E$3)),1,0),0))) -> 0 | L408: =L407+K408 -> 0
A409: =IF('Formation Initiale'!$A11="","",'Formation Initiale'!$A11) -> TR034 | B409: =IF($A409="","",'Formation Initiale'!$E11) -> Toril Rhoys | C409: =IF($A409="","",'Formation Initiale'!$F11) -> Lisbonne | D409: =IF($A409="","",IF('Formation Initiale'!$F11="Lisbonne","B2C (Initiale)","B2C+B2B (Initiale)")) -> B2C (Initiale) | E409: =IF($A409="","",'Formation Initiale'!$B11) -> OS1 | F409: =IF($A409="","",'Formation Initiale'!$G11) -> 46006 | G409: =IF($A409="","",'Formation Initiale'!$H11) -> 46017 | H409: =IF($A409="","",'Formation Initiale'!$L11) -> 0 | I409: =IF($A409="","",'Formation Initiale'!$R11) -> Terminé | K409: =IF(A409="",0,IF(IFERROR(VLOOKUP(A409,Skills!$A:$M,13,FALSE()),"")="COS",0,IF(OR(I409="En cours",I409="À venir",I409="À planifier"),IF(AND(OR($C$3="Tous",$C$3="",C409=$C$3),OR($E$3="Tous",$E$3="",I409=$E$3)),1,0),0))) -> 0 | L409: =L408+K409 -> 0
...

Sheet Skills
A1: ID Agent | B1: Prénom | C1: Nom | D1: Lieu | E1: B2C | F1: B2B | G1: Agences B2C | H1: Agences B2B | I1: Après-vente B2C | J1: Après-vente B2B | K1: Loisirs | L1: Nb compétences | M1: Statut | N1: =HYPERLINK("#Accueil!A1","⌂ Accueil") -> ⌂ Accueil | O1: Quillridge B2C | P1: Quillridge B2B | Q1: Quillridge Agences B2C | R1: Quillridge Agences B2B | S1: Quillridge Après-vente B2C | T1: Quillridge Après-vente B2B | U1: Quillridge Evermont | W1: Groupe | X1: Groupe (saisie)
A2: TR001 | B2: Lumus | C2: Fenel Valeridge | D2: Montréal | E2: =IF($O2="✓","✓",IF(ISNUMBER($O2),TEXT($O2,"yyyy-mm-dd"),IF($A2="","",IF(SUMPRODUCT(('Formation Initiale'!$A$2:$A$999=$A2)*('Formation Initiale'!$R$2:$R$999="Terminé"))>0,"✓",IF(SUMPRODUCT(MAX(('Formation Initiale'!$A$2:$A$999=$A2)*'Formation Initiale'!$G$2:$G$999))>0,TEXT(SUMPRODUCT(MAX(('Formation Initiale'!$A$2:$A$999=$A2)*'Formation Initiale'!$G$2:$G$999)),"yyyy-mm-dd"),""))))) -> ✓ | F2: =IF($P2="✓","✓",IF(ISNUMBER($P2),TEXT($P2,"yyyy-mm-dd"),IF($A2="","",IF($D2="Lisbonne","",IF(SUMPRODUCT(('Formation Initiale'!$A$2:$A$999=$A2)*('Formation Initiale'!$R$2:$R$999="Terminé"))>0,"✓",IF(SUMPRODUCT(MAX(('Formation Initiale'!$A$2:$A$999=$A2)*'Formation Initiale'!$G$2:$G$999))>0,TEXT(SUMPRODUCT(MAX(('Formation Initiale'!$A$2:$A$999=$A2)*'Formation Initiale'!$G$2:$G$999)),"yyyy-mm-dd"),"")))))) -> ✓ | G2: =IF($Q2="✓","✓",IF(ISNUMBER($Q2),TEXT($Q2,"yyyy-mm-dd"),IF($A2="","",IF(SUMPRODUCT(('Agences & Après-vente'!$A$2:$A$1000=$A2)*(('Agences & Après-vente'!$D$2:$D$1000="Agences")+('Agences & Après-vente'!$D$2:$D$1000="Agences et Après-vente"))*('Agences & Après-vente'!$I$2:$I$1000="DONE"))>0,"✓",IF(SUMPRODUCT(MAX(('Agences & Après-vente'!$A$2:$A$1000=$A2)*(('Agences & Après-vente'!$D$2:$D$1000="Agences")+('Agences & Après-vente'!$D$2:$D$1000="Agences et Après-vente"))*'Agences & Après-vente'!$E$2:$E$1000))>0,TEXT(SUMPRODUCT(MAX(('Agences & Après-vente'!$A$2:$A$1000=$A2)*(('Agences & Après-vente'!$D$2:$D$1000="Agences")+('Agences & Après-vente'!$D$2:$D$1000="Agences et Après-vente"))*'Agences & Après-vente'!$E$2:$E$1000)),"yyyy-mm-dd"),""))))) -> ✓ | H2: =IF($R2="✓","✓",IF(ISNUMBER($R2),TEXT($R2,"yyyy-mm-dd"),IF($A2="","",IF($D2="Lisbonne","",IF(SUMPRODUCT(('Agences & Après-vente'!$A$2:$A$1000=$A2)*(('Agences & Après-vente'!$D$2:$D$1000="Agences")+('Agences & Après-vente'!$D$2:$D$1000="Agences et Après-vente"))*('Agences & Après-vente'!$I$2:$I$1000="DONE"))>0,"✓",IF(SUMPRODUCT(MAX(('Agences & Après-vente'!$A$2:$A$1000=$A2)*(('Agences & Après-vente'!$D$2:$D$1000="Agences")+('Agences & Après-vente'!$D$2:$D$1000="Agences et Après-vente"))*'Agences & Après-vente'!$E$2:$E$1000))>0,TEXT(SUMPRODUCT(MAX(('Agences & Après-vente'!$A$2:$A$1000=$A2)*(('Agences & Après-vente'!$D$2:$D$1000="Agences")+('Agences & Après-vente'!$D$2:$D$1000="Agences et Après-vente"))*'Agences & Après-vente'!$E$2:$E$1000)),"yyyy-mm-dd"),"")))))) -> ✓ | I2: =IF($S2="✓","✓",IF(ISNUMBER($S2),TEXT($S2,"yyyy-mm-dd"),IF($A2="","",IF(SUMPRODUCT(('Agences & Après-vente'!$A$2:$A$1000=$A2)*(('Agences & Après-vente'!$D$2:$D$1000="Après-vente")+('Agences & Après-vente'!$D$2:$D$1000="Agences et Après-vente"))*('Agences & Après-vente'!$I$2:$I$1000="DONE"))>0,"✓",IF(SUMPRODUCT(MAX(('Agences & Après-vente'!$A$2:$A$1000=$A2)*(('Agences & Après-vente'!$D$2:$D$1000="Après-vente")+('Agences & Après-vente'!$D$2:$D$1000="Agences et Après-vente"))*'Agences & Après-vente'!$E$2:$E$1000))>0,TEXT(SUMPRODUCT(MAX(('Agences & Après-vente'!$A$2:$A$1000=$A2)*(('Agences & Après-vente'!$D$2:$D$1000="Après-vente")+('Agences & Après-vente'!$D$2:$D$1000="Agences et Après-vente"))*'Agences & Après-vente'!$E$2:$E$1000)),"yyyy-mm-dd"),""))))) -> ✓ | J2: =IF($T2="✓","✓",IF(ISNUMBER($T2),TEXT($T2,"yyyy-mm-dd"),IF($A2="","",IF($D2="Lisbonne","",IF(SUMPRODUCT(('Agences & Après-vente'!$A$2:$A$1000=$A2)*(('Agences & Après-vente'!$D$2:$D$1000="Après-vente")+('Agences & Après-vente'!$D$2:$D$1000="Agences et Après-vente"))*('Agences & Après-vente'!$I$2:$I$1000="DONE"))>0,"✓",IF(SUMPRODUCT(MAX(('Agences & Après-vente'!$A$2:$A$1000=$A2)*(('Agences & Après-vente'!$D$2:$D$1000="Après-vente")+('Agences & Après-vente'!$D$2:$D$1000="Agences et Après-vente"))*'Agences & Après-vente'!$E$2:$E$1000))>0,TEXT(SUMPRODUCT(MAX(('Agences & Après-vente'!$A$2:$A$1000=$A2)*(('Agences & Après-vente'!$D$2:$D$1000="Après-vente")+('Agences & Après-vente'!$D$2:$D$1000="Agences et Après-vente"))*'Agences & Après-vente'!$E$2:$E$1000)),"yyyy-mm-dd"),"")))))) -> ✓ | K2: =IF($U2="✓","✓",IF(ISNUMBER($U2),TEXT($U2,"yyyy-mm-dd"),IF($D2="Lisbonne","",IF($A2="","",IF(SUMPRODUCT((Evermont!$A$2:$A$1000=$A2)*(Evermont!$Q$2:$Q$1000="Terminé"))>0,"✓",IF(SUMPRODUCT(MAX((Evermont!$A$2:$A$1000=$A2)*Evermont!$F$2:$F$1000))>0,TEXT(SUMPRODUCT(MAX((Evermont!$A$2:$A$1000=$A2)*Evermont!$F$2:$F$1000)),"yyyy-mm-dd"),"")))))) | L2: =IF($A2="","",COUNTIF(E2:K2,"✓")) -> 6 | M2: Active | O2: ✓ | P2: ✓ | Q2: ✓ | R2: ✓ | S2: ✓ | T2: ✓ | W2: =IF($A2="","",IF($X2<>"",$X2,IFERROR(INDEX('Formation Initiale'!$B$2:$B$999,MATCH($A2,'Formation Initiale'!$A$2:$A$999,0)),"Général"))) -> Général
